Workbook

Sheet Inputs
A1: Janey's Pension Plan — Inputs & Assumptions
A2: Blue = you can edit. Yellow = confirm the real figure (see notes). Black = calculated — don't overwrite.
A4: Personal details
A5: Current age | B5: 53 | C5: Janey, as at 2026.
A6: Target retirement age | B6: 65
A7: State Pension age | B7: 67 | C7: DOB 05/11/1972 → State Pension age 67, payable from 05/11/2039 (not 65).
A8: Years of contributions (to retirement) | B8: =B6-B5 -> 12
A9: Income-bridge years (retire → State Pension) | B9: =B7-B6 -> 2 | C9: Years living on private pension before the State Pension starts.
A11: Contributions (personal pension / SIPP)
A12: Net amount Janey pays in per year (£) | B12: 2880 | C12: Non-earner maximum: £2,880 net/year. Tax relief is added even with no earned income.
A13: Basic-rate tax relief added (£) | B13: =B12*0.25 -> 720 | C13: 20% relief = net ÷ 0.8 − net = net × 0.25 → £720 on £2,880.
A14: Gross annual contribution (£) | B14: =B12+B13 -> 3600 | C14: This is what actually lands in the pension each year (£3,600).
A15: Existing pension pot value today (£) | B15: 0 | C15: Unknown — set to £0 for now. NOTE: the 1998–2002 school pension is a separate DEFINED-BENEFIT pension (income, not a pot) — see below.
A17: Investment assumptions
A18: Growth — cautious | B18: 0.03
A19: Growth — central (medium risk) | B19: 0.05 | C19: Medium risk appetite → 5% nominal central assumption.
A20: Growth — optimistic | B20: 0.07
A21: Annual charges (platform + fund) | B21: 0.005 | C21: Keep this low — 0.5% vs 1.5% makes a big difference. Set to Janey's actual charges.
A22: Net growth — cautious | B22: =B18-B21 -> 0.025
A23: Net growth — central | B23: =B19-B21 -> 0.045
A24: Net growth — optimistic | B24: =B20-B21 -> 0.065
A25: Inflation (for today's-money view) | B25: 0.025
A26: Sustainable withdrawal rate | B26: 0.04 | C26: Rule-of-thumb sustainable drawdown from the pot each year (~4%).
A28: Other retirement income (annual, today's money)
A29: Full new State Pension per year (£) | B29: 11973 | C29: 2025/26 full rate ≈ £11,973. Verify current figure at gov.uk.
A30: % of full State Pension Janey will qualify for | B30: 1 | C30: UNKNOWN — get a forecast at gov.uk/check-state-pension. As a homemaker there may be NI gaps; filling them is often the best-value action of all.
A31: Janey's State Pension per year (£) | B31: =B29*B30 -> 11973
A32: Janey's Teachers' Pension per year (£) | B32: 6981.65 | C32: Teachers' Pension (deferred, 19 Sep 2026): £6,981.65 from the 80th Final Salary section, payable UNREDUCED from age 60. Index-linked. See the detail block below.
A34: Michael (for the household view)
A35: Michael's current age | B35: 57 | C35: DOB 02/07/1969 (confirmed) → age 57 in 2026.
A36: Michael's target retirement age | B36: 65 | C36: Assumed 65 to match Janey — change to Michael's actual plan.
A37: Michael's years of contributions (to retirement) | B37: =B36-B35 -> 8
A38: Michael's State Pension per week (£) | B38: 241 | C38: From Michael's forecast: £241/week starting Nov 2039.
A39: Michael's State Pension per year (£) | B39: =B38*52 -> 12532 | C39: £241 × 52. DOB 02/07/1969 → State Pension age 67, payable from ~02/07/2036 (earlier than the Nov 2039 first assumed). Confirm the amount at gov.uk/check-state-pension.
A40: Michael's existing pension pot today (£) | B40: 221974.07 | C40: Aegon SIPP — £221,974.07 consolidated from Scottish Equitable (transfer authority, Jun 2024). Excludes his newer NEST pot (current employer) — value unknown, add when known.
A41: Michael's gross annual contribution (£) | B41: 32490 | C41: £2,707.50/mo employer pension × 12 (19% of £171k salary; includes his 10% salary sacrifice). If the £1,425/mo sacrifice is ON TOP, use £49,590. Well within the £60k Annual Allowance.
A42: Michael's pot at retirement (£) | B42: =FV(B23,B37,-B41,-B40,1) -> 634140.15 | C42: Grown at the central net rate. Uses the shared growth/charge assumptions above.
A43: Michael's drawdown income / yr (£) | B43: =B42*B26 -> 25365.606 | C43: ~4% of his pot per year.
A45: Janey's Teachers' Pension — detail (deferred, 19 Sep 2026)
A46: 80th Final Salary pension — NPA 60 (from Nov 2032) | B46: 6981.65 | C46: Payable UNREDUCED from age 60. Index-linked.
...

Sheet Projection
A1: Year-by-year projection — central case (net growth from Inputs)
A2: Contributions assumed paid at the start of each year. Change any input on the Inputs tab and this recalculates.
A4: Year | B4: Age | C4: Opening balance | D4: Contribution (gross) | E4: Growth | F4: Closing balance
A5: 1 | B5: =Inputs!B5+1 -> 54 | C5: =Inputs!B15 -> 0 | D5: =Inputs!B14 -> 3600 | E5: =(C5+D5)*Inputs!B23 -> 162 | F5: =C5+D5+E5 -> 3762
A6: 2 | B6: =B5+1 -> 55 | C6: =F5 -> 3762 | D6: =Inputs!B14 -> 3600 | E6: =(C6+D6)*Inputs!B23 -> 331.29 | F6: =C6+D6+E6 -> 7693.29
A7: 3 | B7: =B6+1 -> 56 | C7: =F6 -> 7693.29 | D7: =Inputs!B14 -> 3600 | E7: =(C7+D7)*Inputs!B23 -> 508.19805 | F7: =C7+D7+E7 -> 11801.488
A8: 4 | B8: =B7+1 -> 57 | C8: =F7 -> 11801.488 | D8: =Inputs!B14 -> 3600 | E8: =(C8+D8)*Inputs!B23 -> 693.06696 | F8: =C8+D8+E8 -> 16094.555
A9: 5 | B9: =B8+1 -> 58 | C9: =F8 -> 16094.555 | D9: =Inputs!B14 -> 3600 | E9: =(C9+D9)*Inputs!B23 -> 886.25498 | F9: =C9+D9+E9 -> 20580.81
A10: 6 | B10: =B9+1 -> 59 | C10: =F9 -> 20580.81 | D10: =Inputs!B14 -> 3600 | E10: =(C10+D10)*Inputs!B23 -> 1088.1364 | F10: =C10+D10+E10 -> 25268.946
A11: 7 | B11: =B10+1 -> 60 | C11: =F10 -> 25268.946 | D11: =Inputs!B14 -> 3600 | E11: =(C11+D11)*Inputs!B23 -> 1299.1026 | F11: =C11+D11+E11 -> 30168.049
A12: 8 | B12: =B11+1 -> 61 | C12: =F11 -> 30168.049 | D12: =Inputs!B14 -> 3600 | E12: =(C12+D12)*Inputs!B23 -> 1519.5622 | F12: =C12+D12+E12 -> 35287.611
A13: 9 | B13: =B12+1 -> 62 | C13: =F12 -> 35287.611 | D13: =Inputs!B14 -> 3600 | E13: =(C13+D13)*Inputs!B23 -> 1749.9425 | F13: =C13+D13+E13 -> 40637.554
A14: 10 | B14: =B13+1 -> 63 | C14: =F13 -> 40637.554 | D14: =Inputs!B14 -> 3600 | E14: =(C14+D14)*Inputs!B23 -> 1990.6899 | F14: =C14+D14+E14 -> 46228.244
A15: 11 | B15: =B14+1 -> 64 | C15: =F14 -> 46228.244 | D15: =Inputs!B14 -> 3600 | E15: =(C15+D15)*Inputs!B23 -> 2242.271 | F15: =C15+D15+E15 -> 52070.515
A16: 12 | B16: =B15+1 -> 65 | C16: =F15 -> 52070.515 | D16: =Inputs!B14 -> 3600 | E16: =(C16+D16)*Inputs!B23 -> 2505.1732 | F16: =C16+D16+E16 -> 58175.688
A18: Totals
A19: Total gross contributed | F19: =SUM(D5:D16) -> 43200
A20: Total investment growth | F20: =SUM(E5:E16) -> 14975.688
A21: Pot at retirement (age 65) | F21: =F16 -> 58175.688

Sheet Retirement income
A1: Retirement income — scenarios & summary
A2: Pots use FV of £3,600/yr for 12 years at each net growth rate. Income figures are illustrative, not guaranteed.
A4: 1) Pot at retirement (age 65)
A5: Scenario | B5: Net growth | C5: Pot at 65
A6: Cautious | B6: =Inputs!B22 -> 0.025 | C6: =FV(Inputs!B22,Inputs!B8,-Inputs!B14,-Inputs!B15,1) -> 50905.59
A7: Central | B7: =Inputs!B23 -> 0.045 | C7: =FV(Inputs!B23,Inputs!B8,-Inputs!B14,-Inputs!B15,1) -> 58175.688
A8: Optimistic | B8: =Inputs!B24 -> 0.065 | C8: =FV(Inputs!B24,Inputs!B8,-Inputs!B14,-Inputs!B15,1) -> 66599.308
A10: 2) Turning the CENTRAL pot into income
A12: Central pot at 65 | B12: =C7 -> 58175.688
A13: Tax-free cash (25%) | B13: =B12*0.25 -> 14543.922 | C13: Available from age 65.
A14: Sustainable drawdown income / yr | B14: =B12*Inputs!B26 -> 2327.0275 | C14: ~4% of the pot per year (illustrative, not guaranteed).
A15: Annuity income / yr (rough) | B15: =B12*0.06 -> 3490.5413 | C15: Very rough at ~6% single-life level rate; real quotes vary with age/health/rates.
A17: 3) Total annual income (using drawdown + DB + State Pension)
A18: Component | B18: Age 65–66 (bridge) | C18: Age 67+ (with SP)
A19: Private pension (drawdown) | B19: =B14 -> 2327.0275 | C19: =B14 -> 2327.0275
A20: Deferred DB (school) pension | B20: =Inputs!B32 -> 6981.65 | C20: =Inputs!B32 -> 6981.65
A21: State Pension | B21: 0 | C21: =Inputs!B31 -> 11973
A22: Total annual income | B22: =SUM(B19:B21) -> 9308.6775 | C22: =SUM(C19:C21) -> 21281.678
A24: Note: pot figures are in FUTURE money. In today's money, divide by (1+inflation)^12 ≈ divide by 1.34 at 2.5% inflation. State Pension & DB above are already in today's money.
A26: Highest-leverage actions (not just the £3,600/yr):
A27: 1. Get Janey's State Pension forecast (gov.uk/check-state-pension) — fill NI gaps if any.
A28: 2. Teachers' Pension is confirmed: £6,982/yr + £20,945 tax-free lump sum from AGE 60 — this covers the pre-State-Pension years well.
A29: 3. Decide when to take the Teachers' 80th pension (age 60 unreduced) vs. the personal pot vs. State Pension at 67.
A30: 4. Consider whether Michael can contribute more, or use ISAs, for the household.

Sheet Household
A1: Household retirement income — Janey + Michael
A2: Steady state: both retired and both State Pensions in payment (from ~2039–2040). Fill Michael's pot & contributions on the Inputs tab to complete his private pension.
A4: Annual income (steady state)
A5: Component | B5: Janey | C5: Michael | D5: Household
A6: Private pension (drawdown ~4%) | B6: ='Retirement income'!B14 -> 2327.0275 | C6: =Inputs!B43 -> 25365.606 | D6: =B6+C6 -> 27692.634
A7: DB / service pension (Teachers' · RAF) | B7: =Inputs!B32 -> 6981.65 | C7: =Inputs!B53 -> 5340 | D7: =B7+C7 -> 12321.65
A8: State Pension | B8: =Inputs!B31 -> 11973 | C8: =Inputs!B39 -> 12532 | D8: =B8+C8 -> 24505
A9: Total annual income | B9: =SUM(B6:B8) -> 21281.678 | C9: =SUM(C6:C8) -> 43237.606 | D9: =SUM(D6:D8) -> 64519.284
A10: ≈ per month | D10: =D9/12 -> 5376.607
A12: Against PLSA couple benchmarks (today's money)
A13: Standard | B13: Couple / yr | C13: Household vs benchmark
A14: Minimum | B14: 22400 | C14: =D9-B14 -> 42119.284
A15: Moderate | B15: 43100 | C15: =D9-B15 -> 21419.284
A16: Comfortable | B16: 59000 | C16: =D9-B16 -> 5519.2836
A17: PLSA couple figures are illustrative — verify current values at retirementlivingstandards.org.uk.
A19: Notes
A20: • Private-pension (drawdown) figures are in FUTURE money; State Pension & DB are in today's money — treat the total as indicative.
A21: • Timing: Michael's State Pension starts Nov 2039; Janey's at age 67 (~2040). Each has a short gap between retiring at 65 and their State Pension starting — plan those bridge years.
A22: • Michael's private pension shows £0 until his pot and contributions are entered on the Inputs tab (cells B41, B42).
A23: • The £500k mortgage-free home is a household asset, not counted as income here — it can support later-life options (e.g. downsizing).
A24: • This is planning material, not regulated financial advice.
